Workbook
Name Elder_A.E._Obakpe: 'NO 7'!$B$3
Name Obakpe: 'NO 7'!$A$3:$J$4

Sheet SUMMARY
B2: BEULAH MULTI-PURPOSE COOPERATIVE SOCIETY LTD.
B3: DETAILS AS AT 31ST MAY, 2026
B4: S/N | C4: NAMES | D4: COOP NO | E4: SHARES | F4: SPECIAL SAVINGS | G4: SAVINGS BALANCE | H4: LOANS BALANCE | I4: LOAN INT. BALANCE
B5: 1 | C5: O/S P.O. Odeyemi | D5: BC01 | G5: ='NO 1'!D8 -> 6000
B6: 2 | C6: Eld. V.O. Ogegengbe | D6: BC02 | G6: ='NO 2'!D10 -> 76025
B7: 3 | C7: Eld. M.A. Adeagbo | D7: BC03 | G7: ='No 3'!D11 -> 155000
B8: 4 | C8: Eld. S.K. Ogunjimi | D8: BC04 | H8: ='No 4'!G8 -> -284255.02
B9: 5 | C9: Eld. Ibikunle Samson | D9: BC05 | H9: ='NO 5'!G8 -> -31104.81
B10: 6 | C10: Eld. G. E. Leramo | D10: BC06
B11: 7 | C11: Elder A.E. Obakpe | D11: BC07 | H11: ='NO 7'!G8 -> -432961.1
B12: 8 | C12: Eld. J.O. Adeleye | D12: BC08 | G12: ='NO 8'!D11 -> 32913.76
B13: 9 | C13: Eld. P.O. Olabintan | D13: BC09 | H13: ='NO 9'!G8 -> -31429.7
B14: 10 | C14: Eld. J.I. Evbotokhai | D14: BC10 | G14: ='NO 10'!D16 -> 426000
B15: 11 | C15: Eld. Luke Dauda | D15: BC11 | G15: ='NO 11'!D8 -> 5000
B16: 12 | C16: Eld. P.O. Ogunseye | D16: BC12 | H16: ='NO 12'!G8 -> -89573.88
B17: 13 | C17: Eld. S. A. Oyemayo | D17: BC13 | H17: ='NO 13'!G8 -> -420050.29
B18: 14 | C18: Dcn. Dauda Philip | D18: BC14 | G18: ='NO 14'!D8 -> 33500
B19: 15 | C19: Dcn Jeremiah Dauda | D19: BC15
B20: 16 | C20: Dcn. U.O. Uwem | D20: BC16 | H20: ='NO 16'!G10 -> -923243.32
B21: 17 | C21: Dns J.B. Odeyemi | D21: BC17 | G21: =+'NO 17'!D9 -> 643500
B22: 18 | C22: Dns. V.Y. Olutola | D22: BC18 | G22: ='NO 18'!D8 -> 312750 | H22: ='NO 18'!G10 -> 425000 | I22: ='NO 18'!J10 -> 0
B23: 19 | C23: Dns. F.F. Ayeni | D23: BC19 | G23: ='NO 19'!D9 -> 3000
B24: 20 | C24: Dns E.O. Leramo | D24: BC20 | G24: ='NO 20'!D11 -> 128500
B25: 21 | C25: Dns Balogun Blessing I. | D25: BC21
B26: 22 | C26: Dns. O.O. Evbotokhai | D26: BC22 | G26: ='NO 22'!D8 -> 17215
B27: 23 | C27: Dns. A.M. Adeagbo | D27: BC23 | G27: ='NO 23'!D9 -> 13000
B28: 24 | C28: Dns. M.B. Adeleye | D28: BC24 | G28: ='NO 24'!D9 -> 7000
B29: 25 | C29: Dns. R.O. Ojo | D29: BC25 | G29: ='NO 25'!D8 -> 9500
B30: 26 | C30: Dns H.B. Ibikunle | D30: BC26
B31: 27 | C31: Dns. F.M. Olabintan | D31: BC27 | G31: ='NO 27'!D8 -> 14000
B32: 28 | C32: Dns. O.O. Ogedengbe | D32: BC28 | G32: ='NO 28'!D8 -> 21085
B33: 29 | C33: Dns. Dauda Luke S. | D33: BC29
B34: 30 | C34: Dns. B.H. Oyemayo | D34: BC30 | G34: ='NO 30'!D8 -> 23000
B35: 31 | C35: Bro. Mathew Alaba | D35: BC31 | G35: ='NO 31'!D10 -> 60000
B36: 32 | C36: Bro. Panmoh Isaiah | D36: BC32 | H36: ='NO 32'!G8 -> -419.27
B37: 33 | C37: Bro. Balogun Samuel | D37: BC33 | G37: ='NO 33'!D8 -> 16564.9
B38: 34 | C38: Sis. Mary Odeyemi | D38: BC34 | G38: ='NO 34'!D8 -> 25000
B39: 35 | C39: Bro. Samuel David Ukoidem | D39: BC35 | H39: ='NO 35'!G9 -> -214504.7
B40: 36 | C40: Bro. J.I. Adeleye | D40: BC36
B41: 37 | C41: Bro David David Ukoidem | D41: BC37 | G41: ='NO 37'!D9 -> 67000
...

Sheet NO 1
A1: BEULAH MULTI-PURPOSE COOP SOCIETY LTD
A2: MEMBER'S PASSBOOK LEDGER AS AT DATE
A3: NAME | B3: O/S P.O. Odeyemi | D3: BC01
A4: PHONE NUMBER
A5: Entrance fee | C5: 1000
A6: DATE | B6: SAVINGS | E6: LOANS | H6: LOANS INTEREST
B7: DR | C7: CR | D7: BALANCE | E7: DR | F7: CR | G7: BALANCE | H7: DR | I7: CR | J7: BALANCE
A8: 45747 | D8: 6000

Sheet NO 2
A1: BEULAH MULTI-PURPOSE COOP SOCIETY LTD
A2: MEMBER'S PASSBOOK LEDGER AS AT DATE
A3: NAME | B3: Eld. V.O. Ogegengbe | D3: BC02
A4: PHONE NUMBER
A5: Entrance fee | C5: 1000
A6: DATE | B6: SAVINGS | E6: LOANS | H6: LOANS INTEREST
B7: DR | C7: CR | D7: BALANCE | E7: DR | F7: CR | G7: BALANCE | H7: DR | I7: CR | J7: BALANCE
A8: 45747 | D8: 0
A9: 45770 | C9: 56025 | D9: =+C9 -> 56025
A10: 46065 | C10: 20000 | D10: =+D9+C10 -> 76025
A30: TOTAL | E30: =SUM(E8:E29) -> 0 | F30: =SUM(F8:F29) -> 0 | G30: =SUM(G8:G29) -> 0 | H30: =SUM(H8:H29) -> 0 | I30: =SUM(I8:I29) -> 0 | J30: =SUM(J8:J29) -> 0

Sheet No 3
A1: BEULAH MULTI-PURPOSE COOP SOCIETY LTD
A2: MEMBER'S PASSBOOK LEDGER AS AT DATE
A3: NAME | B3: Eld. M.A. Adeagbo | D3: BC03
A4: PHONE NUMBER
A6: DATE | B6: SAVINGS | E6: LOANS | H6: LOANS INTEREST
B7: DR | C7: CR | D7: BALANCE | E7: DR | F7: CR | G7: BALANCE | H7: DR | I7: CR | J7: BALANCE
A8: 45747 | D8: 115000
A9: 46040 | C9: 10000 | D9: =+D8+C9 -> 125000
A10: 46077 | C10: 20000 | D10: =+D9+C10 -> 145000
A11: 46159 | C11: 10000 | D11: =+D10+C11 -> 155000

Sheet No 4
A1: BEULAH MULTI-PURPOSE COOP SOCIETY LTD
A2: MEMBER'S PASSBOOK LEDGER AS AT DATE
A3: NAME | B3: ELD S.K. Ogunjimi | D3: BC04
A4: PHONE NUMBER
A6: DATE | B6: SAVINGS | E6: LOANS | H6: LOANS INTEREST
B7: DR | C7: CR | D7: BALANCE | E7: DR | F7: CR | G7: BALANCE | H7: DR | I7: CR | J7: BALANCE
A8: 45747 | F8: -284255.02 | G8: =F8 -> -284255.02

Sheet NO 5
A1: BEULAH MULTI-PURPOSE COOP SOCIETY LTD
A2: MEMBER'S PASSBOOK LEDGER AS AT DATE
A3: NAME | B3: Elder S.B. Ibikunle
A4: PHONE NUMBER | D4: BC05
A5: Entrance fee | C5: 1000
A6: DATE | B6: SAVINGS | E6: LOANS | H6: LOANS INTEREST
B7: DR | C7: CR | D7: BALANCE | E7: DR | F7: CR | G7: BALANCE | H7: DR | I7: CR | J7: BALANCE
A8: 45747 | F8: -31104.81 | G8: =F8 -> -31104.81

Sheet NO 6
A1: BEULAH MULTI-PURPOSE COOP SOCIETY LTD
A2: MEMBER'S PASSBOOK LEDGER AS AT DATE
A3: NAME | B3: Eld. G. E. Leramo | D3: BC06
A4: PHONE NUMBER
A6: DATE | B6: SAVINGS | E6: LOANS | H6: LOANS INTEREST
B7: DR | C7: CR | D7: BALANCE | E7: DR | F7: CR | G7: BALANCE | H7: DR | I7: CR | J7: BALANCE
A8: 45747 | D8: 0

Sheet NO 7
A1: BEULAH MULTI-PURPOSE COOP SOCIETY LTD
A2: MEMBER'S PASSBOOK LEDGER AS AT DATE
A3: NAME | B3: Elder A.E. Obakpe | D3: BC07
A4: PHONE NUMBER
A5: Entrance fee | C5: 1000
A6: DATE | B6: SAVINGS | E6: LOANS | H6: LOANS INTEREST
B7: DR | C7: CR | D7: BALANCE | E7: DR | F7: CR | G7: BALANCE | H7: DR | I7: CR | J7: BALANCE
A8: 45747 | F8: -432961.1 | G8: =F8 -> -432961.1

Sheet NO 8
A1: BEULAH MULTI-PURPOSE COOP SOCIETY LTD
A2: MEMBER'S PASSBOOK LEDGER AS AT DATE
A3: NAME | B3: Eld. J.O. Adeleye | D3: BC08
A4: PHONE NUMBER
A6: DATE | B6: SAVINGS | E6: LOANS | H6: LOANS INTEREST
B7: DR | C7: CR | D7: BALANCE | E7: DR | F7: CR | G7: BALANCE | H7: DR | I7: CR | J7: BALANCE
A8: 45747 | D8: -7086.24
A9: 46048 | C9: 20000 | D9: =+D8+C9 -> 12913.76
A10: 46097 | C10: 10000 | D10: =+D9+C10 -> 22913.76
A11: 46114 | C11: 10000 | D11: =+D10+C11 -> 32913.76

Sheet NO 9
A1: BEULAH MULTI-PURPOSE COOP SOCIETY LTD
A2: MEMBER'S PASSBOOK LEDGER AS AT DATE
A3: NAME | B3: Eld P. Olabintan | D3: BC09
A4: PHONE NUMBER
A5: Entrance fee
A6: DATE | B6: SAVINGS | E6: LOANS | H6: LOANS INTEREST
B7: DR | C7: CR | D7: BALANCE | E7: DR | F7: CR | G7: BALANCE | H7: DR | I7: CR | J7: BALANCE
A8: 45747 | F8: -31429.7 | G8: =F8 -> -31429.7

Sheet NO 10
A1: BEULAH MULTI-PURPOSE COOP SOCIETY LTD
A2: MEMBER'S PASSBOOK LEDGER AS AT DATE
A3: NAME | B3: Eld J. I. Evbotokhai | D3: BC10
A4: PHONE NUMBER
A6: DATE | B6: SAVINGS | E6: LOANS | H6: LOANS INTEREST
B7: DR | C7: CR | D7: BALANCE | E7: DR | F7: CR | G7: BALANCE | H7: DR | I7: CR | J7: BALANCE
A8: 45747 | D8: 83500
A9: 45774 | C9: 50000 | D9: =+D8+C9 -> 133500
A10: 45775 | F10: 150000 | G10: =+F10 -> 150000 | H10: 7500 | J10: =+H10 -> 7500
A11: 45810 | E11: 42500 | G11: =+G10-E11 -> 107500 | I11: 7500 | J11: =+J10-I11 -> 0
A12: 45853 | C12: 192500 | D12: =+D9+C12 -> 326000 | E12: 107500 | G12: =+G11-E12 -> 0
A13: 46028 | F13: 300000 | G13: =+F13 -> 300000 | H13: 15000 | J13: =+H13 -> 15000
A14: 46054 | E14: 85000 | G14: =+G13-E14 -> 215000 | I14: 15000 | J14: =+H13-I14 -> 0
A15: 46082 | C15: =300000-215000 -> 85000 | D15: =+D12+C15 -> 411000 | F15: 215000 | G15: =G14-F15 -> 0 | H15: =+G14-F15 -> 0
A16: 46082 | C16: 15000 | D16: =+D15+C16 -> 426000

Sheet NO 11
A1: BEULAH MULTI-PURPOSE COOP SOCIETY LTD
A2: MEMBER'S PASSBOOK LEDGER AS AT DATE
A3: NAME | B3: Eld. Luke Dauda | D3: BC11
A4: PHONE NUMBER
A6: DATE | B6: SAVINGS | E6: LOANS | H6: LOANS INTEREST
B7: DR | C7: CR | D7: BALANCE | E7: DR | F7: CR | G7: BALANCE | H7: DR | I7: CR | J7: BALANCE
A8: 45747 | D8: 5000

Sheet NO 12
A1: BEULAH MULTI-PURPOSE COOP SOCIETY LTD
A2: MEMBER'S PASSBOOK LEDGER AS AT DATE
A3: NAME | B3: Eld. P.O. Ogunseye | D3: BC12
A4: PHONE NUMBER
A6: DATE | B6: SAVINGS | E6: LOANS | H6: LOANS INTEREST
B7: DR | C7: CR | D7: BALANCE | E7: DR | F7: CR | G7: BALANCE | H7: DR | I7: CR | J7: BALANCE
A8: 45747 | F8: -89573.88 | G8: =+F8 -> -89573.88

Sheet NO 13
A1: BEULAH MULTI-PURPOSE COOP SOCIETY LTD
A2: MEMBER'S PASSBOOK LEDGER AS AT DATE
A3: NAME | B3: Eld A.S. Oyemayo | D3: BC13
A4: PHONE NUMBER
A6: DATE | B6: SAVINGS | E6: LOANS | H6: LOANS INTEREST
B7: DR | C7: CR | D7: BALANCE | E7: DR | F7: CR | G7: BALANCE | H7: DR | I7: CR | J7: BALANCE
A8: 46112 | F8: -420050.29 | G8: =+F8 -> -420050.29

Sheet NO 14
A1: BEULAH MULTI-PURPOSE COOP SOCIETY LTD
A2: MEMBER'S PASSBOOK LEDGER AS AT DATE
A3: NAME | B3: Dcn Philip Dauda | D3: BC14
A4: PHONE NUMBER
A6: DATE | B6: SAVINGS | E6: LOANS | H6: LOANS INTEREST
B7: DR | C7: CR | D7: BALANCE | E7: DR | F7: CR | G7: BALANCE | H7: DR | I7: CR | J7: BALANCE
A8: 45747 | D8: 33500

Sheet NO 15
A1: BEULAH MULTI-PURPOSE COOP SOCIETY LTD
A2: MEMBER'S PASSBOOK LEDGER AS AT DATE
A3: NAME | B3: Dcn Jeremiah Dauda | D3: BC15
A4: PHONE NUMBER
A6: DATE | B6: SAVINGS | E6: LOANS | H6: LOANS INTEREST
B7: DR | C7: CR | D7: BALANCE | E7: DR | F7: CR | G7: BALANCE | H7: DR | I7: CR | J7: BALANCE
A8: 45747 | D8: 0

Sheet NO 16
A1: BEULAH MULTI-PURPOSE COOP SOCIETY LTD
A2: MEMBER'S PASSBOOK LEDGER AS AT DATE
A3: NAME | B3: Dcn. U.O. Uwem | D3: BC16
A4: PHONE NUMBER
A5: Entrance fee | C5: 1000
A6: DATE | B6: SAVINGS | E6: LOANS | H6: LOANS INTEREST
B7: DR | C7: CR | D7: BALANCE | E7: DR | F7: CR | G7: BALANCE | H7: DR | I7: CR | J7: BALANCE
A8: 45747 | G8: -1033243.3
A9: 45879 | E9: 30000 | G9: =+G8+E9 -> -1003243.3
A10: 46087 | E10: 80000 | G10: =G9+E10 -> -923243.32
D22: =D15 -> 0 | G22: =G15 -> 0 | J22: =J15 -> 0

Sheet NO 17
A1: BEULAH MULTI-PURPOSE COOP SOCIETY LTD
A2: MEMBER'S PASSBOOK LEDGER AS AT DATE
A3: NAME | B3: Dns J.B. Odeyemi | D3: BC17
A4: PHONE NUMBER
A5: Entrance fee | C5: 1000
A6: DATE | B6: SAVINGS | E6: LOANS | H6: LOANS INTEREST
B7: DR | C7: CR | D7: BALANCE | E7: DR | F7: CR | G7: BALANCE | H7: DR | I7: CR | J7: BALANCE
A8: 45747 | D8: 543500
A9: 46136 | C9: 100000 | D9: =+D8+C9 -> 643500

Sheet NO 18
A1: BEULAH MULTI-PURPOSE COOP SOCIETY LTD
A2: MEMBER'S PASSBOOK LEDGER AS AT DATE
A3: NAME | B3: Dns. V.Y. Olutola | D3: BC18
A4: PHONE NUMBER
A6: DATE | B6: SAVINGS | E6: LOANS | H6: LOANS INTEREST
B7: DR | C7: CR | D7: BALANCE | E7: DR | F7: CR | G7: BALANCE | H7: DR | I7: CR | J7: BALANCE
A8: 45747 | D8: 312750
A9: 46077 | F9: 500000 | G9: =F9 -> 500000 | H9: 25000 | J9: =H9 -> 25000
A10: 46143 | E10: 75000 | G10: =G9-E10 -> 425000 | I10: 25000 | J10: =J9-I10 -> 0

Sheet NO 19
A1: BEULAH MULTI-PURPOSE COOP SOCIETY LTD
A2: MEMBER'S PASSBOOK LEDGER AS AT DATE
A3: NAME | B3: Dns. F.F. Ayeni | D3: BC19
A4: PHONE NUMBER
A5: Entrance fee | C5: 2000
A6: DATE | B6: SAVINGS | E6: LOANS | H6: LOANS INTEREST
B7: DR | C7: CR | D7: BALANCE | E7: DR | F7: CR | G7: BALANCE | H7: DR | I7: CR | J7: BALANCE
A8: 45747 | D8: 0
A9: 46049 | C9: 3000 | D9: =+D8+C9 -> 3000

Sheet NO 20
A1: BEULAH MULTI-PURPOSE COOP SOCIETY LTD
A2: MEMBER'S PASSBOOK LEDGER AS AT DATE
A3: NAME | B3: Dcns E.O. Leramo | D3: BC20
A4: PHONE NUMBER
A6: DATE | B6: SAVINGS | E6: LOANS | H6: LOANS INTEREST
B7: DR | C7: CR | D7: BALANCE | E7: DR | F7: CR | G7: BALANCE | H7: DR | I7: CR | J7: BALANCE
A8: 45747 | D8: 119500
A9: 46060 | C9: 1000 | D9: =+D8+C9 -> 120500
A10: 46124 | C10: 4000 | D10: =+D9+C10 -> 124500
A11: 46152 | C11: 4000 | D11: =+D10+C11 -> 128500

Sheet NO 21
A1: BEULAH MULTI-PURPOSE COOP SOCIETY LTD
A2: MEMBER'S PASSBOOK LEDGER AS AT DATE
A3: NAME | B3: Dns Balogun Blessing I. | D3: BC21
A4: PHONE NUMBER
A5: Entrance fee | C5: 1000
A6: DATE | B6: SAVINGS | E6: LOANS | H6: LOANS INTEREST
B7: DR | C7: CR | D7: BALANCE | E7: DR | F7: CR | G7: BALANCE | H7: DR | I7: CR | J7: BALANCE
A8: 45747 | D8: 0

Sheet NO 22
A1: BEULAH MULTI-PURPOSE COOP SOCIETY LTD
A2: MEMBER'S PASSBOOK LEDGER AS AT DATE
A3: NAME | B3: Dns. O.O. Evbotokhai | D3: BC22
A4: PHONE NUMBER
A6: DATE | B6: SAVINGS | E6: LOANS | H6: LOANS INTEREST
B7: DR | C7: CR | D7: BALANCE | E7: DR | F7: CR | G7: BALANCE | H7: DR | I7: CR | J7: BALANCE
A8: 45747 | D8: 17215

Sheet NO 23
A1: BEULAH MULTI-PURPOSE COOP SOCIETY LTD
A2: MEMBER'S PASSBOOK LEDGER AS AT DATE
A3: NAME | B3: Dns. A.M. Adeagbo | D3: BC23
A4: PHONE NUMBER
A5: Entrance fee | C5: 1000
A6: DATE | B6: SAVINGS | E6: LOANS | H6: LOANS INTEREST
B7: DR | C7: CR | D7: BALANCE | E7: DR | F7: CR | G7: BALANCE | H7: DR | I7: CR | J7: BALANCE
A8: 45747 | D8: 9000
A9: 46151 | C9: 4000 | D9: =+D8+C9 -> 13000

Sheet NO 24
A1: BEULAH MULTI-PURPOSE COOP SOCIETY LTD
A2: MEMBER'S PASSBOOK LEDGER AS AT DATE
A3: NAME | B3: Dns. M.B. Adeleye | D3: BC24
A4: PHONE NUMBER
A6: DATE | B6: SAVINGS | E6: LOANS | H6: LOANS INTEREST
B7: DR | C7: CR | D7: BALANCE | E7: DR | F7: CR | G7: BALANCE | H7: DR | I7: CR | J7: BALANCE
A8: 45747 | D8: 2000
A9: 46142 | C9: 5000 | D9: =+D8+C9 -> 7000

Sheet NO 25
A1: BEULAH MULTI-PURPOSE COOP SOCIETY LTD
A2: MEMBER'S PASSBOOK LEDGER AS AT DATE
A3: NAME | B3: Dns. R.O. Ojo | D3: BC25
A4: PHONE NUMBER
A5: Entrance fee | C5: 1000
A6: DATE | B6: SAVINGS | E6: LOANS | H6: LOANS INTEREST
B7: DR | C7: CR | D7: BALANCE | E7: DR | F7: CR | G7: BALANCE | H7: DR | I7: CR | J7: BALANCE
A8: 45747 | D8: 9500

Sheet NO 26
A1: BEULAH MULTI-PURPOSE COOP SOCIETY LTD
A2: MEMBER'S PASSBOOK LEDGER AS AT DATE
A3: NAME | B3: Dns H.B. Ibikunle | D3: BC26
A4: PHONE NUMBER
A6: DATE | B6: SAVINGS | E6: LOANS | H6: LOANS INTEREST
B7: DR | C7: CR | D7: BALANCE | E7: DR | F7: CR | G7: BALANCE | H7: DR | I7: CR | J7: BALANCE
A8: 45747 | D8: 0

Sheet NO 27
A1: BEULAH MULTI-PURPOSE COOP SOCIETY LTD
A2: MEMBER'S PASSBOOK LEDGER AS AT DATE
A3: NAME | B3: Dns. F.M. Olabintan | D3: BC27
A4: PHONE NUMBER
A6: DATE | B6: SAVINGS | E6: LOANS | H6: LOANS INTEREST
B7: DR | C7: CR | D7: BALANCE | E7: DR | F7: CR | G7: BALANCE | H7: DR | I7: CR | J7: BALANCE
A8: 45747 | D8: 14000

Sheet NO 28
A1: BEULAH MULTI-PURPOSE COOP SOCIETY LTD
A2: MEMBER'S PASSBOOK LEDGER AS AT DATE
A3: NAME | B3: Dns. O.O. Ogedengbe | D3: BC28
A4: PHONE NUMBER
A6: DATE | B6: SAVINGS | E6: LOANS | H6: LOANS INTEREST
B7: DR | C7: CR | D7: BALANCE | E7: DR | F7: CR | G7: BALANCE | H7: DR | I7: CR | J7: BALANCE
A8: 45747 | D8: 21085

Sheet NO 29
A1: BEULAH MULTI-PURPOSE COOP SOCIETY LTD
A2: MEMBER'S PASSBOOK LEDGER AS AT DATE
A3: NAME | B3: Dns. Dauda Luke S. | D3: BC29
A4: PHONE NUMBER
A5: Entrance fee | C5: 1000
A6: DATE | B6: SAVINGS | E6: LOANS | H6: LOANS INTEREST
B7: DR | C7: CR | D7: BALANCE | E7: DR | F7: CR | G7: BALANCE | H7: DR | I7: CR | J7: BALANCE
A8: 45747 | D8: 0

Sheet NO 30
A1: BEULAH MULTI-PURPOSE COOP SOCIETY LTD
A2: MEMBER'S PASSBOOK LEDGER AS AT DATE
A3: NAME | B3: Dns. B.H. Oyemayo | D3: BC30
A4: PHONE NUMBER
A5: Entrance fee | C5: 1000
A6: DATE | B6: SAVINGS | E6: LOANS | H6: LOANS INTEREST
B7: DR | C7: CR | D7: BALANCE | E7: DR | F7: CR | G7: BALANCE | H7: DR | I7: CR | J7: BALANCE
A8: 45747 | D8: 23000

Sheet NO 31
A1: BEULAH MULTI-PURPOSE COOP SOCIETY LTD
A2: MEMBER'S PASSBOOK LEDGER AS AT DATE
A3: NAME | B3: Bro. Mathew Alaba | D3: BC31
A4: PHONE NUMBER
A5: Entrance fee | C5: 1000
A6: DATE | B6: SAVINGS | E6: LOANS | H6: LOANS INTEREST
B7: DR | C7: CR | D7: BALANCE | E7: DR | F7: CR | G7: BALANCE | H7: DR | I7: CR | J7: BALANCE
A8: 45747 | D8: -19178.5
A9: 46142 | C9: 19178.5 | D9: =D8+C9 -> 0
A10: 46142 | C10: 60000 | D10: =+D9+C10 -> 60000

Sheet NO 32
A1: BEULAH MULTI-PURPOSE COOP SOCIETY LTD
A2: MEMBER'S PASSBOOK LEDGER AS AT DATE
A3: NAME | B3: Bro. Panmoh Isaiah | D3: BC32
A4: PHONE NUMBER
A6: DATE | B6: SAVINGS | E6: LOANS | H6: LOANS INTEREST
B7: DR | C7: CR | D7: BALANCE | E7: DR | F7: CR | G7: BALANCE | H7: DR | I7: CR | J7: BALANCE
A8: 45747 | F8: -419.27 | G8: =+F8 -> -419.27

Sheet NO 33
A1: BEULAH MULTI-PURPOSE COOP SOCIETY LTD
A2: MEMBER'S PASSBOOK LEDGER AS AT DATE
A3: NAME | B3: Bro. Balogun Samuel | D3: BC33
A4: PHONE NUMBER
A6: DATE | B6: SAVINGS | E6: LOANS | H6: LOANS INTEREST
B7: DR | C7: CR | D7: BALANCE | E7: DR | F7: CR | G7: BALANCE | H7: DR | I7: CR | J7: BALANCE
A8: 45747 | D8: 16564.9

Sheet NO 34
A1: BEULAH MULTI-PURPOSE COOP SOCIETY LTD
A2: MEMBER'S PASSBOOK LEDGER AS AT DATE
A3: NAME | B3: Sis. Mary Odeyemi | D3: BC34
A4: PHONE NUMBER
A5: Entrance fee | C5: 2000
A6: DATE | B6: SAVINGS | E6: LOANS | H6: LOANS INTEREST
B7: DR | C7: CR | D7: BALANCE | E7: DR | F7: CR | G7: BALANCE | H7: DR | I7: CR | J7: BALANCE
A8: 46159 | C8: 25000 | D8: =+C8 -> 25000

Sheet NO 35
A1: BEULAH MULTI-PURPOSE COOP SOCIETY LTD
A2: MEMBER'S PASSBOOK LEDGER AS AT DATE
A3: NAME | B3: Bro. Samuel David Ukoidem | D3: BC35
A4: PHONE NUMBER
A5: Entrance fee | C5: 1000
A6: DATE | B6: SAVINGS | E6: LOANS | H6: LOANS INTEREST
B7: DR | C7: CR | D7: BALANCE | E7: DR | F7: CR | G7: BALANCE | H7: DR | I7: CR | J7: BALANCE
A8: 45747 | F8: -244504.7 | G8: =F8 -> -244504.7
A9: 46087 | E9: 30000 | G9: =+G8+E9 -> -214504.7

Sheet NO 36
A1: BEULAH MULTI-PURPOSE COOP SOCIETY LTD
A2: MEMBER'S PASSBOOK LEDGER AS AT DATE
A3: NAME | B3: Bro. J.I. Adeleye | D3: BC36
A4: PHONE NUMBER
A5: Entrance fee | C5: 1000
A6: DATE | B6: SAVINGS | E6: LOANS | H6: LOANS INTEREST
B7: DR | C7: CR | D7: BALANCE | E7: DR | F7: CR | G7: BALANCE | H7: DR | I7: CR | J7: BALANCE
A8: 45747 | D8: 0

Sheet NO 37
A1: BEULAH MULTI-PURPOSE COOP SOCIETY LTD
A2: MEMBER'S PASSBOOK LEDGER AS AT DATE
A3: NAME | B3: Bro David David Ukoidem | D3: BC37
A4: PHONE NUMBER
A6: DATE | B6: SAVINGS | E6: LOANS | H6: LOANS INTEREST
B7: DR | C7: CR | D7: BALANCE | E7: DR | F7: CR | G7: BALANCE | H7: DR | I7: CR | J7: BALANCE
A8: 45747 | D8: 17000
A9: 46113 | C9: 50000 | D9: =+D8+C9 -> 67000

Sheet NO 38
A1: BEULAH MULTI-PURPOSE COOP SOCIETY LTD
A2: MEMBER'S PASSBOOK LEDGER AS AT DATE
A3: NAME | B3: Bro Sunday Olaitan Tope | D3: BC38
A4: PHONE NUMBER
A5: Entrance fee | C5: 1000
A6: DATE | B6: SAVINGS | E6: LOANS | H6: LOANS INTEREST
B7: DR | C7: CR | D7: BALANCE | E7: DR | F7: CR | G7: BALANCE | H7: DR | I7: CR | J7: BALANCE
A8: 45747 | F8: -19809.13 | G8: =+F8 -> -19809.13

Sheet NO 39
A1: BEULAH MULTI-PURPOSE COOP SOCIETY LTD
A2: MEMBER'S PASSBOOK LEDGER AS AT DATE
A3: NAME | B3: Sis. G.R. Balogun | D3: BC39
A4: PHONE NUMBER
A5: Entrance fee | C5: 1000
A6: DATE | B6: SAVINGS | E6: LOANS | H6: LOANS INTEREST
B7: DR | C7: CR | D7: BALANCE | E7: DR | F7: CR | G7: BALANCE | H7: DR | I7: CR | J7: BALANCE
A8: 45747 | D8: 10000

Sheet NO 40
A1: BEULAH MULTI-PURPOSE COOP SOCIETY LTD
A2: MEMBER'S PASSBOOK LEDGER AS AT DATE
A3: NAME | B3: Sis. Obake Phoebe | D3: BC40
A4: PHONE NUMBER
A5: Entrance fee | C5: 1000
A6: DATE | B6: SAVINGS | E6: LOANS | H6: LOANS INTEREST
B7: DR | C7: CR | D7: BALANCE | E7: DR | F7: CR | G7: BALANCE | H7: DR | I7: CR | J7: BALANCE
A8: 45747 | F8: -5846.12 | G8: =+F8 -> -5846.12

Sheet NO 41
A1: BEULAH MULTI-PURPOSE COOP SOCIETY LTD
A2: MEMBER'S PASSBOOK LEDGER AS AT DATE
A3: NAME | B3: Sis. Matthew O. Blessing | D3: BC41
A4: PHONE NUMBER
A5: Entrance fee | C5: 1000
A6: DATE | B6: SAVINGS | E6: LOANS | H6: LOANS INTEREST
B7: DR | C7: CR | D7: BALANCE | E7: DR | F7: CR | G7: BALANCE | H7: DR | I7: CR | J7: BALANCE
A8: 45747 | D8: 0

Sheet NO 42
A1: BEULAH MULTI-PURPOSE COOP SOCIETY LTD
A2: MEMBER'S PASSBOOK LEDGER AS AT DATE
A3: NAME | B3: Sis. Ogedengbe Eyitayo Deborah | D3: BC42
A4: PHONE NUMBER
A6: DATE | B6: SAVINGS | E6: LOANS | H6: LOANS INTEREST
B7: DR | C7: CR | D7: BALANCE | E7: DR | F7: CR | G7: BALANCE | H7: DR | I7: CR | J7: BALANCE
A8: 45747 | D8: 1000

Sheet NO 43
A1: BEULAH MULTI-PURPOSE COOP SOCIETY LTD
A2: MEMBER'S PASSBOOK LEDGER AS AT DATE
A3: NAME | B3: Dcns Olaniawo | D3: BC43
A4: PHONE NUMBER
A5: Entrance fee | C5: 1000
A6: DATE | B6: SAVINGS | E6: LOANS | H6: LOANS INTEREST
B7: DR | C7: CR | D7: BALANCE | E7: DR | F7: CR | G7: BALANCE | H7: DR | I7: CR | J7: BALANCE
A8: 45747 | D8: 0

Sheet NO 44
A1: BEULAH MULTI-PURPOSE COOP SOCIETY LTD
A2: MEMBER'S PASSBOOK LEDGER AS AT DATE
A3: NAME | B3: Sis Alfred Rachel | D3: BC44
A4: PHONE NUMBER
A5: Entrance fee | C5: 1000
A6: DATE | B6: SAVINGS | E6: LOANS | H6: LOANS INTEREST
B7: DR | C7: CR | D7: BALANCE | E7: DR | F7: CR | G7: BALANCE | H7: DR | I7: CR | J7: BALANCE
A8: 45747 | D8: 1684

Sheet NO 45
A1: BEULAH MULTI-PURPOSE COOP SOCIETY LTD
A2: MEMBER'S PASSBOOK LEDGER AS AT DATE
A3: NAME | B3: Bro. Alfred Victor | D3: BC45
A4: PHONE NUMBER
A6: DATE | B6: SAVINGS | E6: LOANS | H6: LOANS INTEREST
B7: DR | C7: CR | D7: BALANCE | E7: DR | F7: CR | G7: BALANCE | H7: DR | I7: CR | J7: BALANCE
A8: 45747 | D8: 3600

Sheet NO 46
A1: BEULAH MULTI-PURPOSE COOP SOCIETY LTD
A2: MEMBER'S PASSBOOK LEDGER AS AT DATE
A3: NAME | B3: Sis. M.O. Eniwaye | D3: BC46
A4: PHONE NUMBER
A6: DATE | B6: SAVINGS | E6: LOANS | H6: LOANS INTEREST
B7: DR | C7: CR | D7: BALANCE | E7: DR | F7: CR | G7: BALANCE | H7: DR | I7: CR | J7: BALANCE
A8: 45747 | D8: 5050
A9: 46061 | C9: 50000 | D9: =+D8+C9 -> 55050
A10: 46089 | C10: 50000 | D10: =+D9+C10 -> 105050
A11: 46122 | C11: 50000 | D11: =+D10+C11 -> 155050
A12: 46159 | C12: 50000 | D12: =+D11+C12 -> 205050
A13: 46172 | C13: 50000 | D13: =+D12+C13 -> 255050

Sheet NO 47
A1: BEULAH MULTI-PURPOSE COOP SOCIETY LTD
A2: MEMBER'S PASSBOOK LEDGER AS AT DATE
A3: NAME | B3: Sis. Tosin Matthew | D3: BC47
A4: PHONE NUMBER
A6: DATE | B6: SAVINGS | E6: LOANS | H6: LOANS INTEREST
B7: DR | C7: CR | D7: BALANCE | E7: DR | F7: CR | G7: BALANCE | H7: DR | I7: CR | J7: BALANCE
A8: 45747

Sheet NO 48
A1: BEULAH MULTI-PURPOSE COOP SOCIETY LTD
A2: MEMBER'S PASSBOOK LEDGER AS AT DATE
A3: NAME | B3: Sis. Taiwo Ibikunle | D3: BC48
A4: PHONE NUMBER
A6: DATE | B6: SAVINGS | E6: LOANS | H6: LOANS INTEREST
B7: DR | C7: CR | D7: BALANCE | E7: DR | F7: CR | G7: BALANCE | H7: DR | I7: CR | J7: BALANCE
A8: 45747

Sheet NO 49
A1: BEULAH MULTI-PURPOSE COOP SOCIETY LTD
A2: MEMBER'S PASSBOOK LEDGER AS AT DATE
A3: NAME | B3: O/S Ayodele | D3: BC49
A4: PHONE NUMBER
A6: DATE | B6: SAVINGS | E6: LOANS | H6: LOANS INTEREST
B7: DR | C7: CR | D7: BALANCE | E7: DR | F7: CR | G7: BALANCE | H7: DR | I7: CR | J7: BALANCE
A8: 45747

Sheet NO 50
A1: BEULAH MULTI-PURPOSE COOP SOCIETY LTD
A2: MEMBER'S PASSBOOK LEDGER AS AT DATE
A3: NAME | B3: Dcns A.O. Peter | D3: BC50
A4: PHONE NUMBER
A6: DATE | B6: SAVINGS | E6: LOANS | H6: LOANS INTEREST
B7: DR | C7: CR | D7: BALANCE | E7: DR | F7: CR | G7: BALANCE | H7: DR | I7: CR | J7: BALANCE
A8: 45747 | D8: 21320
A9: 46111 | C9: 5000 | D9: =+D8+C9 -> 26320

Sheet NO 51
A1: BEULAH MULTI-PURPOSE COOP SOCIETY LTD
A2: MEMBER'S PASSBOOK LEDGER AS AT DATE
A3: NAME | B3: Dns Grace Ukpong | D3: BC51
A4: PHONE NUMBER
A6: DATE | B6: SAVINGS | E6: LOANS | H6: LOANS INTEREST
B7: DR | C7: CR | D7: BALANCE | E7: DR | F7: CR | G7: BALANCE | H7: DR | I7: CR | J7: BALANCE
A8: 45747

Sheet NO 52
A1: BEULAH MULTI-PURPOSE COOP SOCIETY LTD
A2: MEMBER'S PASSBOOK LEDGER AS AT DATE
A3: NAME | B3: Bro. M.O. Eniwaye | D3: BC52
A4: PHONE NUMBER
A5: Entrance fee | C5: 1000
A6: DATE | B6: SAVINGS | E6: LOANS | H6: LOANS INTEREST
B7: DR | C7: CR | D7: BALANCE | E7: DR | F7: CR | G7: BALANCE | H7: DR | I7: CR | J7: BALANCE
A8: 45747 | D8: 0
A9: 46020 | C9: 5000 | D9: =+D8+C9 -> 5000

Sheet NO 53
A1: BEULAH MULTI-PURPOSE COOP SOCIETY LTD
A2: MEMBER'S PASSBOOK LEDGER AS AT DATE
A3: NAME | B3: Bro. Israel Olutola | D3: BC53
A4: PHONE NUMBER
A5: Entrance fee | C5: 2000
A6: DATE | B6: SAVINGS | E6: LOANS | H6: LOANS INTEREST
B7: DR | C7: CR | D7: BALANCE | E7: DR | F7: CR | G7: BALANCE | H7: DR | I7: CR | J7: BALANCE
A8: 45747

Sheet NO 54
A1: BEULAH MULTI-PURPOSE COOP SOCIETY LTD
A2: MEMBER'S PASSBOOK LEDGER AS AT DATE
A3: NAME | B3: Sis. Deborah Leramo | D3: BC54
A4: PHONE NUMBER
A5: Entrance fee | C5: 2000
A6: DATE | B6: SAVINGS | E6: LOANS | H6: LOANS INTEREST
B7: DR | C7: CR | D7: BALANCE | E7: DR | F7: CR | G7: BALANCE | H7: DR | I7: CR | J7: BALANCE
A8: 45747
A9: 46060 | C9: 15000 | D9: 15000
A10: 46124 | C10: 4000 | D10: =+D9+C10 -> 19000
A11: 46152 | C11: 4000 | D11: =+D10+C11 -> 23000

Sheet NO 55
A1: BEULAH MULTI-PURPOSE COOP SOCIETY LTD
A2: MEMBER'S PASSBOOK LEDGER AS AT DATE
A3: NAME | B3: Bro. Daniel Leramo | D3: BC55
A4: PHONE NUMBER
A5: Entrance fee | C5: 2000
A6: DATE | B6: SAVINGS | E6: LOANS | H6: LOANS INTEREST
B7: DR | C7: CR | D7: BALANCE | E7: DR | F7: CR | G7: BALANCE | H7: DR | I7: CR | J7: BALANCE
A9: 46060 | C9: 10000 | D9: =+C9 -> 10000
A10: 46124 | C10: 4000 | D10: =+D9+C10 -> 14000
A11: 46152 | C11: 4000 | D11: =+D10+C11 -> 18000

Sheet NO 56
A1: BEULAH MULTI-PURPOSE COOP SOCIETY LTD
A2: MEMBER'S PASSBOOK LEDGER AS AT DATE
A3: NAME | B3: Bro. Adeagbo Adeyemi | D3: BC56
A4: PHONE NUMBER
A5: Entrance fee | C5: 2000
A6: DATE | B6: SAVINGS | E6: LOANS | H6: LOANS INTEREST
B7: DR | C7: CR | D7: BALANCE | E7: DR | F7: CR | G7: BALANCE | H7: DR | I7: CR | J7: BALANCE

Sheet NO 57
A1: BEULAH MULTI-PURPOSE COOP SOCIETY LTD
A2: MEMBER'S PASSBOOK LEDGER AS AT DATE
A3: NAME | B3: Bro. Adeagbo Ademola | D3: BC57
A4: PHONE NUMBER
A5: Entrance fee | C5: 2000
A6: DATE | B6: SAVINGS | E6: LOANS | H6: LOANS INTEREST
B7: DR | C7: CR | D7: BALANCE | E7: DR | F7: CR | G7: BALANCE | H7: DR | I7: CR | J7: BALANCE

Sheet NO 58
A1: BEULAH MULTI-PURPOSE COOP SOCIETY LTD
A2: MEMBER'S PASSBOOK LEDGER AS AT DATE
A3: NAME | B3: Bro. Adeagbo Adebayo | D3: BC58
A4: PHONE NUMBER
A5: Entrance fee | C5: 2000
A6: DATE | B6: SAVINGS | E6: LOANS | H6: LOANS INTEREST
B7: DR | C7: CR | D7: BALANCE | E7: DR | F7: CR | G7: BALANCE | H7: DR | I7: CR | J7: BALANCE

Sheet NO 59
A1: BEULAH MULTI-PURPOSE COOP SOCIETY LTD
A2: MEMBER'S PASSBOOK LEDGER AS AT DATE
A3: NAME | B3: Bro. Adeagbo Aderola | D3: BC59
A4: PHONE NUMBER
A5: Entrance fee | C5: 2000
A6: DATE | B6: SAVINGS | E6: LOANS | H6: LOANS INTEREST
B7: DR | C7: CR | D7: BALANCE | E7: DR | F7: CR | G7: BALANCE | H7: DR | I7: CR | J7: BALANCE

Sheet NO 60
A1: BEULAH MULTI-PURPOSE COOP SOCIETY LTD
A2: MEMBER'S PASSBOOK LEDGER AS AT DATE
A3: NAME | B3: Sis. Janet Pashemibo Mark | D3: BC60
A4: PHONE NUMBER
A5: Entrance fee | C5: 2000
A6: DATE | B6: SAVINGS | E6: LOANS | H6: LOANS INTEREST
B7: DR | C7: CR | D7: BALANCE | E7: DR | F7: CR | G7: BALANCE | H7: DR | I7: CR | J7: BALANCE
A8: 46138 | C8: 8000 | D8: =+C8 -> 8000

Sheet NO 61
A1: BEULAH MULTI-PURPOSE COOP SOCIETY LTD
A2: MEMBER'S PASSBOOK LEDGER AS AT DATE
A3: NAME | B3: Mary Awetalumilo Mark | D3: BC61
A4: PHONE NUMBER
A5: Entrance fee | C5: 2000
A6: DATE | B6: SAVINGS | E6: LOANS | H6: LOANS INTEREST
B7: DR | C7: CR | D7: BALANCE | E7: DR | F7: CR | G7: BALANCE | H7: DR | I7: CR | J7: BALANCE
A8: 46146 | C8: 3000 | D8: =+C8 -> 3000
A9: 46173 | C9: 20000 | D9: =+D8+C9 -> 23000

Sheet NO 62
A1: BEULAH MULTI-PURPOSE COOP SOCIETY LTD
A2: MEMBER'S PASSBOOK LEDGER AS AT DATE
A3: NAME | B3: Sis. Esther Fayinnya Mark | D3: BC62
A4: PHONE NUMBER
A5: Entrance fee | C5: 2000
A6: DATE | B6: SAVINGS | E6: LOANS | H6: LOANS INTEREST
B7: DR | C7: CR | D7: BALANCE | E7: DR | F7: CR | G7: BALANCE | H7: DR | I7: CR | J7: BALANCE
A8: 46146 | C8: 8000 | D8: =+C8 -> 8000
A9: 46172 | C9: 10000 | D9: =+D8+C9 -> 18000

Sheet NO 63
A1: BEULAH MULTI-PURPOSE COOP SOCIETY LTD
A2: MEMBER'S PASSBOOK LEDGER AS AT DATE
A3: NAME | D3: BC63
A4: PHONE NUMBER
A5: Entrance fee
A6: DATE | B6: SAVINGS | E6: LOANS | H6: LOANS INTEREST
B7: DR | C7: CR | D7: BALANCE | E7: DR | F7: CR | G7: BALANCE | H7: DR | I7: CR | J7: BALANCE

Sheet NO 64
A1: BEULAH MULTI-PURPOSE COOP SOCIETY LTD
A2: MEMBER'S PASSBOOK LEDGER AS AT DATE
A3: NAME | D3: BC64
A4: PHONE NUMBER
A5: Entrance fee
A6: DATE | B6: SAVINGS | E6: LOANS | H6: LOANS INTEREST
B7: DR | C7: CR | D7: BALANCE | E7: DR | F7: CR | G7: BALANCE | H7: DR | I7: CR | J7: BALANCE

Sheet NO 65
A1: BEULAH MULTI-PURPOSE COOP SOCIETY LTD
A2: MEMBER'S PASSBOOK LEDGER AS AT DATE
A3: NAME | D3: BC65
A4: PHONE NUMBER
A5: Entrance fee
A6: DATE | B6: SAVINGS | E6: LOANS | H6: LOANS INTEREST
B7: DR | C7: CR | D7: BALANCE | E7: DR | F7: CR | G7: BALANCE | H7: DR | I7: CR | J7: BALANCE

Sheet NO 66
A1: BEULAH MULTI-PURPOSE COOP SOCIETY LTD
A2: MEMBER'S PASSBOOK LEDGER AS AT DATE
A3: NAME | D3: BC66
A4: PHONE NUMBER
A5: Entrance fee
A6: DATE | B6: SAVINGS | E6: LOANS | H6: LOANS INTEREST
B7: DR | C7: CR | D7: BALANCE | E7: DR | F7: CR | G7: BALANCE | H7: DR | I7: CR | J7: BALANCE

Sheet NO 67
A1: BEULAH MULTI-PURPOSE COOP SOCIETY LTD
A2: MEMBER'S PASSBOOK LEDGER AS AT DATE
A3: NAME | D3: BC67
A4: PHONE NUMBER
A5: Entrance fee
A6: DATE | B6: SAVINGS | E6: LOANS | H6: LOANS INTEREST
B7: DR | C7: CR | D7: BALANCE | E7: DR | F7: CR | G7: BALANCE | H7: DR | I7: CR | J7: BALANCE

Sheet NO 68
A1: BEULAH MULTI-PURPOSE COOP SOCIETY LTD
A2: MEMBER'S PASSBOOK LEDGER AS AT DATE
A3: NAME | D3: BC68
A4: PHONE NUMBER
A5: Entrance fee
A6: DATE | B6: SAVINGS | E6: LOANS | H6: LOANS INTEREST
B7: DR | C7: CR | D7: BALANCE | E7: DR | F7: CR | G7: BALANCE | H7: DR | I7: CR | J7: BALANCE

Sheet NO 69
A1: BEULAH MULTI-PURPOSE COOP SOCIETY LTD
A2: MEMBER'S PASSBOOK LEDGER AS AT DATE
A3: NAME | D3: BC69
A4: PHONE NUMBER
A5: Entrance fee
A6: DATE | B6: SAVINGS | E6: LOANS | H6: LOANS INTEREST
B7: DR | C7: CR | D7: BALANCE | E7: DR | F7: CR | G7: BALANCE | H7: DR | I7: CR | J7: BALANCE

Sheet NO 70
A1: BEULAH MULTI-PURPOSE COOP SOCIETY LTD
A2: MEMBER'S PASSBOOK LEDGER AS AT DATE
A3: NAME | D3: BC70
A4: PHONE NUMBER
A5: Entrance fee
A6: DATE | B6: SAVINGS | E6: LOANS | H6: LOANS INTEREST
B7: DR | C7: CR | D7: BALANCE | E7: DR | F7: CR | G7: BALANCE | H7: DR | I7: CR | J7: BALANCE

Sheet NO 71
A1: BEULAH MULTI-PURPOSE COOP SOCIETY LTD
A2: MEMBER'S PASSBOOK LEDGER AS AT DATE
A3: NAME | D3: BC71
A4: PHONE NUMBER
A5: Entrance fee
A6: DATE | B6: SAVINGS | E6: LOANS | H6: LOANS INTEREST
B7: DR | C7: CR | D7: BALANCE | E7: DR | F7: CR | G7: BALANCE | H7: DR | I7: CR | J7: BALANCE

Sheet NO 72
A1: BEULAH MULTI-PURPOSE COOP SOCIETY LTD
A2: MEMBER'S PASSBOOK LEDGER AS AT DATE
A3: NAME | D3: BC72
A4: PHONE NUMBER
A5: Entrance fee
A6: DATE | B6: SAVINGS | E6: LOANS | H6: LOANS INTEREST
B7: DR | C7: CR | D7: BALANCE | E7: DR | F7: CR | G7: BALANCE | H7: DR | I7: CR | J7: BALANCE

Sheet NO 73
A1: BEULAH MULTI-PURPOSE COOP SOCIETY LTD
A2: MEMBER'S PASSBOOK LEDGER AS AT DATE
A3: NAME | D3: BC73
A4: PHONE NUMBER
A5: Entrance fee
A6: DATE | B6: SAVINGS | E6: LOANS | H6: LOANS INTEREST
B7: DR | C7: CR | D7: BALANCE | E7: DR | F7: CR | G7: BALANCE | H7: DR | I7: CR | J7: BALANCE

Sheet NO 74
A1: BEULAH MULTI-PURPOSE COOP SOCIETY LTD
A2: MEMBER'S PASSBOOK LEDGER AS AT DATE
A3: NAME | D3: BC74
A4: PHONE NUMBER
A5: Entrance fee
A6: DATE | B6: SAVINGS | E6: LOANS | H6: LOANS INTEREST
B7: DR | C7: CR | D7: BALANCE | E7: DR | F7: CR | G7: BALANCE | H7: DR | I7: CR | J7: BALANCE

Sheet NO 75
A1: BEULAH MULTI-PURPOSE COOP SOCIETY LTD
A2: MEMBER'S PASSBOOK LEDGER AS AT DATE
A3: NAME | D3: BC75
A4: PHONE NUMBER
A5: Entrance fee
A6: DATE | B6: SAVINGS | E6: LOANS | H6: LOANS INTEREST
B7: DR | C7: CR | D7: BALANCE | E7: DR | F7: CR | G7: BALANCE | H7: DR | I7: CR | J7: BALANCE

Sheet NO 76
A1: BEULAH MULTI-PURPOSE COOP SOCIETY LTD
A2: MEMBER'S PASSBOOK LEDGER AS AT DATE
A3: NAME | D3: BC76
A4: PHONE NUMBER
A5: Entrance fee
A6: DATE | B6: SAVINGS | E6: LOANS | H6: LOANS INTEREST
B7: DR | C7: CR | D7: BALANCE | E7: DR | F7: CR | G7: BALANCE | H7: DR | I7: CR | J7: BALANCE

Sheet NO 77
A1: BEULAH MULTI-PURPOSE COOP SOCIETY LTD
A2: MEMBER'S PASSBOOK LEDGER AS AT DATE
A3: NAME | D3: BC77
A4: PHONE NUMBER
A5: Entrance fee
A6: DATE | B6: SAVINGS | E6: LOANS | H6: LOANS INTEREST
B7: DR | C7: CR | D7: BALANCE | E7: DR | F7: CR | G7: BALANCE | H7: DR | I7: CR | J7: BALANCE

Sheet NO 78
A1: BEULAH MULTI-PURPOSE COOP SOCIETY LTD
A2: MEMBER'S PASSBOOK LEDGER AS AT DATE
A3: NAME | D3: BC78
A4: PHONE NUMBER
A5: Entrance fee
A6: DATE | B6: SAVINGS | E6: LOANS | H6: LOANS INTEREST
B7: DR | C7: CR | D7: BALANCE | E7: DR | F7: CR | G7: BALANCE | H7: DR | I7: CR | J7: BALANCE

Sheet NO 79
A1: BEULAH MULTI-PURPOSE COOP SOCIETY LTD
A2: MEMBER'S PASSBOOK LEDGER AS AT DATE
A3: NAME | D3: BC79
A4: PHONE NUMBER
A5: Entrance fee
A6: DATE | B6: SAVINGS | E6: LOANS | H6: LOANS INTEREST
B7: DR | C7: CR | D7: BALANCE | E7: DR | F7: CR | G7: BALANCE | H7: DR | I7: CR | J7: BALANCE

Sheet NO 80
A1: BEULAH MULTI-PURPOSE COOP SOCIETY LTD
A2: MEMBER'S PASSBOOK LEDGER AS AT DATE
A3: NAME | D3: BC80
A4: PHONE NUMBER
A5: Entrance fee
A6: DATE | B6: SAVINGS | E6: LOANS | H6: LOANS INTEREST
B7: DR | C7: CR | D7: BALANCE | E7: DR | F7: CR | G7: BALANCE | H7: DR | I7: CR | J7: BALANCE
